Workbook

Sheet 26년 01월
A1: [ 1월 주차 매출 내역 ]
A2: 거래처 구분 | B2: 거래처 | C2: 매출액(VAT포함) | D2: 매출(입금)일 | E2: 결재형태 | F2: 비고
A3: 입주사 | B3: 연치과 | C3: 200000 | D3: 46036 | E3: 카드 | F3: 10분65매, 30분145매
B4: 호산나성물 | C4: 132000 | D4: 46024 | E4: 계산서
B5: 두리세무사 | C5: 132000 | D5: 46028 | E5: 계산서
B6: 청송나주곰탕 | C6: 132000 | D6: 46024 | E6: 계산서
B7: 커피광 | C7: 132000 | D7: 46024 | E7: 계산서 | F7: 12/31선결제
B8: 까미노브 | C8: 132000 | D8: 46036 | E8: 카드
B9: 까미노브 | E9: 카드 | F9: 10*30매,30*40매,60*25매
B15: 소계 | C15: =SUM(C3:C14) -> 860000
A16: 직원정기 | B16: 정진삼 | E16: 카드 | F16: 직무관련 1~2월 주차료 면제
B17: 박창식 | C17: 80000 | D17: 46035 | E17: 카드
B18: 정지은 | C18: 160000 | D18: 46024 | E18: 카드 | F18: 25년12월분 포함
B19: 이정민 | C19: 80000 | D19: 46027 | E19: 카드
B20: 김슬애 | C20: 80000 | D20: 46030 | E20: 카드
B21: 김상현 | C21: 80000 | D21: 46038 | E21: 카드
B22: 이희원 | C22: 80000 | D22: 46024 | E22: 카드
B23: 김정준 | C23: 80000 | D23: 46030 | E23: 카드 | F23: 1월신규
B24: 신지혜 | F24: 직무관련 1~2월 주차료 면제
B25: 임현정 | F25: 직무관련 1~2월 주차료 면제
B26: 엄재현 | F26: 직무관련 1~2월 주차료 면제
B27: 합창단지휘자 | C27: 80000 | D27: 46045 | E27: 현금
B35: 소계 | C35: =sum(C16:C34) -> 720000
A36: 직원일일 | B36: 문수영 | C36: 40000 | D36: 46024 | E36: 카드 | F36: 윤수영12/26일자포함,김지현포함
B37: 정병창 | C37: 10000 | D37: 46027 | E37: 카드
B38: 민성식 | C38: 10000 | D38: 46028 | E38: 카드 | F38: 25년12/16일자
B39: 김태경 | C39: 10000 | D39: 46030 | E39: 카드
B40: 조규만 | C40: 20000 | D40: 46031 | E40: 카드 | F40: 12월24일자포함
B41: 김혜영 | C41: 20000 | D41: 46034 | E41: 카드 | F41: 1/7일,9일자
B42: 송창환 | C42: 20000 | D42: 46043 | E42: 카드 | F42: 25년12/31일자포함
B43: 남창우 | C43: 20000 | D43: 46045 | E43: 카드 | F43: 윤수현포함
B44: 송창환 | C44: 10000 | D44: 46049 | E44: 카드
E45: 카드
E46: 카드
B55: 소계 | C55: =sum(C36:C54) -> 160000
A56: 관리실 정기 | B56: 서정민 | C56: 80000 | D56: 46024 | E56: 카드
B60: 소계 | C60: =sum(C56:C59) -> 80000
A61: 관리실 일일
B70: 소계 | C70: =SUM(C61:C69) -> 0
A71: 일반 정기 | B71: 마노종건 | C71: 250000 | D71: 46024 | E71: 카드
...

Sheet 26년 02월
A1: [ 2월 주차 매출 내역 ]
A2: 거래처 구분 | B2: 거래처 | C2: 매출액(VAT포함) | D2: 매출(입금)일 | E2: 결재형태 | F2: 비고
A3: 입주사 | B3: 연치과 | C3: 200000 | D3: 46076 | E3: 카드 | F3: 10분65매, 30분145매
B4: 호산나성물 | C4: 132000 | D4: 46055 | E4: 계산서
B5: 두리세무사 | C5: 132000 | D5: 46059 | E5: 계산서
B6: 청송나주곰탕 | C6: 132000 | D6: 46056 | E6: 계산서
B7: 커피광 | C7: 132000 | D7: 46056 | E7: 계산서 | F7: 1/29일 선결제
B8: 까미노브 | C8: 132000 | D8: 46073 | E8: 카드
B9: 까미노브 | E9: 카드 | F9: 10*30매,30*40매,60*25매
B10: 커피광 | C10: 132000 | D10: 46080 | E10: 계산서 | F10: 3월분선결제
B15: 소계 | C15: =sum(C3:C14) -> 992000
A16: 직원정기 | B16: 정진삼 | F16: 직무관련 1~2월 주차료 면제
B17: 박창식 | C17: 80000 | D17: 46066 | E17: 카드
B18: 정지은 | C18: 80000 | D18: 46079 | E18: 카드
B19: 이정민 | C19: 80000 | D19: 46057 | E19: 카드
B20: 김슬애 | C20: 80000 | D20: 46065 | E20: 카드
B21: 김상현 | C21: 80000 | D21: 46057 | E21: 카드
E22: 카드
B23: 김정준 | C23: 80000 | D23: 46059 | E23: 카드
B24: 신지혜 | F24: 직무관련 1~2월 주차료 면제
B25: 임현정 | F25: 직무관련 1~2월 주차료 면제
B26: 엄재현 | F26: 직무관련 1~2월 주차료 면제
B27: 합창단지휘자 | C27: 80000 | D27: 46076 | E27: 계산서
B35: 소계 | C35: =sum(C16:C34) -> 560000
A36: 직원일일 | B36: 조규만 | C36: 10000 | D36: 46055 | E36: 카드
B37: 조규만 | C37: 30000 | D37: 46058 | E37: 카드 | F37: 2/3일자포함, 박현주
B38: 김성일 | C38: 20000 | D38: 46059 | E38: 카드 | F38: 박수정포함
B39: 김성일 | C39: 10000 | D39: 46063 | E39: 카드 | F39: 2/9일자
B40: 박현주 | C40: 10000 | D40: 46066 | E40: 카드
B41: 양주한 | C41: 30000 | D41: 46072 | E41: 카드 | F41: 1/15입자 정병창,박현진포함
B42: 박현진 | C42: 10000 | D42: 46073 | E42: 카드
B43: 김혜영 | C43: 20000 | D43: 46076 | E43: 카드 | F43: 박현진포함
B44: 송창환 | C44: 10000 | D44: 46079 | E44: 카드 | F44: 2/19일자
E45: 카드
E46: 카드
E47: 카드
E48: 카드
E49: 카드
E50: 카드
B55: 소계 | C55: =sum(C36:C54) -> 150000
...

Sheet 26년 03월
A1: [ 3월 주차 매출 내역 ]
A2: 거래처 구분 | B2: 거래처 | C2: 매출액(VAT포함) | D2: 매출(입금)일 | E2: 결재형태 | F2: 비고
A3: 입주사 | B3: 연치과 | E3: 카드 | F3: 10분65매, 30분145매
B4: 호산나성물 | C4: 132000 | D4: 46084 | E4: 계산서
B5: 두리세무사 | C5: 132000 | D5: 46087 | E5: 계산서
B6: 청송나주곰탕 | C6: 132000 | D6: 46084 | E6: 계산서
B7: 까미노브 | C7: 132000 | D7: 46097 | E7: 카드
B8: 까미노브 | E8: 카드 | F8: 10*30매,30*40매,60*25매
B9: 커피광 | C9: 132000 | D9: 46111 | E9: 계산서
B15: 소계 | C15: =sum(C3:C14) -> 660000
A16: 직원정기 | B16: 정진삼 | C16: 80000 | D16: 46087 | E16: 카드
B17: 박창식 | C17: 80000 | D17: 46093 | E17: 카드
B18: 정지은 | C18: 80000 | D18: 46105 | E18: 카드
B19: 이정민 | C19: 80000 | D19: 46084 | E19: 카드
B20: 김슬애 | C20: 80000 | D20: 46084 | E20: 카드
B21: 김상현 | C21: 80000 | D21: 46099 | E21: 카드
B22: 김정준 | C22: 80000 | D22: 46090 | E22: 카드
B23: 합창단지휘자 | C23: 80000 | D23: 46104 | E23: 현금
B24: 신지혜 | F24: 3~4월 업무관련 감면
B35: 소계 | C35: =sum(C16:C34) -> 640000
A36: 직원일일 | B36: 김혜영 | C36: 10000 | D36: 46085 | E36: 카드
B37: 김혜선 | C37: 10000 | D37: 46093 | E37: 카드
B38: 김성일 | C38: 20000 | D38: 46097 | E38: 카드 | F38: 3/9,10일2일분
B39: 백영민 | C39: 10000 | D39: 46101 | E39: 카드
B40: 김혜영 | C40: 20000 | D40: 46106 | E40: 카드 | F40: 민성식포함
B41: 양주한 | C41: 10000 | D41: 46108 | E41: 카드
B55: 소계 | C55: =sum(C36:C54) -> 80000
A56: 관리실 정기 | B56: 서정민 | C56: 80000 | D56: 46085 | E56: 카드
B60: 소계 | C60: =sum(C56:C58) -> 80000
A61: 관리실 일일
B70: 소계 | C70: =SUM(C61:C69) -> 0
A71: 일반 정기 | B71: 마노종건 | C71: 250000 | D71: 46084 | E71: 카드
B72: 마노(양지승) | C72: 250000 | D72: 46084 | E72: 카드
B73: 성화세계 | C73: 250000 | D73: 46084 | E73: 카드
B74: 권혁구 | C74: 250000 | D74: 46084 | E74: 카드
B75: 박성준 | C75: 250000 | D75: 46084 | E75: 카드
B76: 맘스터치 | E76: 카드 | F76: 60분40매,30분20매
B77: 최성제치과 | C77: 400000 | D77: 46086 | E77: 카드 | F77: 60분40매,30분50매,10분10매
B78: 맘스터치(조윤희) | E78: 카드 | F78: 해 지
B79: 신형철 | C79: 250000 | D79: 46084 | E79: 카드
...

Sheet 26년 04월
A2: 거래처 구분 | B2: 거래처 | C2: 매출액(VAT포함) | D2: 매출(입금)일 | E2: 결재형태 | F2: 비고
A3: 입주사 | B3: 연치과 | C3: 200000 | D3: 46129 | E3: 카드 | F3: 10분65매, 30분145매
B4: 호산나성물 | C4: 132000 | D4: 46113 | E4: 계산서
B5: 두리세무사 | C5: 132000 | D5: 46118 | E5: 계산서
B6: 청송나주곰탕 | C6: 132000 | D6: 46113 | E6: 계산서
B7: 커피광 | D7: 46111 | E7: 계산서 | F7: 선결제
B8: 까미노브 | C8: 132000 | D8: 46127 | E8: 카드
B9: 까미노브 | E9: 카드 | F9: 10*30매,30*40매,60*25매
B15: 소계 | C15: =sum(C3:C14) -> 728000
A16: 직원정기 | B16: 정진삼 | E16: 카드 | F16: 4~5월 업무관련 감면
B17: 박창식 | C17: 80000 | D17: 46125 | E17: 카드
B18: 정지은 | C18: 80000 | D18: 46135 | E18: 카드
B19: 이정민 | C19: 80000 | D19: 46113 | E19: 카드
B20: 김슬애 | C20: 80000 | D20: 46114 | E20: 카드
B21: 김상현 | C21: 80000 | D21: 46118 | E21: 카드
B22: 김정준 | C22: 80000 | D22: 46121 | E22: 카드
B23: 신지혜 | E23: 카드 | F23: 3~4월 업무관련 감면
B24: 이학주 | C24: 80000 | D24: 46119 | E24: 카드
B25: 합창단지휘자 | C25: 80000 | D25: 46135 | E25: 계산서
B35: 소계 | C35: =sum(C16:C34) -> 640000
A36: 직원일일 | B36: 양주한 | C36: 10000 | D36: 46115 | E36: 카드
B37: 남창우 | C37: 20000 | D37: 46119 | E37: 카드 | F37: 신의석(3/26일자) ,4/2알자
B38: 양주한 | C38: 20000 | D38: 46122 | E38: 카드 | F38: 이정석(4/2일자포함)
B39: 김혜영 | C39: 20000 | D39: 46129 | E39: 카드 | F39: 임지영포함
E40: 카드
E41: 카드
E42: 카드
E43: 카드
E44: 카드
B55: 소계 | C55: =sum(C36:C49) -> 70000
A56: 관리실 정기 | B56: 서정민 | C56: 80000 | D56: 46114 | E56: 카드
B60: 소계 | C60: =sum(C56:C58) -> 80000
A61: 관리실 일일
B70: 소계 | C70: =SUM(C61:C69) -> 0
A71: 일반 정기 | B71: 마노종건 | C71: 250000 | D71: 46113 | E71: 카드
B72: 마노(양지승) | C72: 250000 | D72: 46113 | E72: 카드
B73: 성화세계 | C73: 250000 | D73: 46118 | E73: 카드
B74: 권혁구 | C74: 250000 | D74: 46115 | E74: 카드
B75: 박성준 | C75: 250000 | D75: 46115 | E75: 카드
B76: 맘스터치 | E76: 카드 | F76: 60분40매,30분20매
...

Sheet 26년 05월
A1: [ 5월 주차 매출 내역 ]
A2: 거래처 구분 | B2: 거래처 | C2: 매출액(VAT포함) | D2: 매출(입금)일 | E2: 결재형태 | F2: 비고
A3: 입주사 | B3: 연치과 | E3: 카드 | F3: 10분65매, 30분145매
B4: 호산나성물 | E4: 계산서
B5: 두리세무사 | E5: 계산서
B6: 청송나주곰탕 | E6: 계산서
B7: 커피광 | E7: 계산서 | F7: 선결제
B8: 까미노브 | E8: 카드
B9: 까미노브 | E9: 카드 | F9: 10*30매,30*40매,60*25매
B15: 소계 | C15: =sum(C3:C14) -> 0
A16: 직원정기 | B16: 정진삼 | E16: 카드 | F16: 4~5월 업무관련 감면
B17: 박창식 | E17: 카드
B18: 정지은 | E18: 카드
B19: 이정민 | E19: 카드
B20: 김슬애 | E20: 카드
B21: 김상현 | E21: 카드
B22: 김정준 | E22: 카드
B23: 이학주 | E23: 카드
B24: 합창단지휘자 | E24: 계산서
B35: 소계 | C35: =sum(C16:C34) -> 0
A36: 직원일일
B55: 소계 | C55: =sum(C36:C54) -> 0
A56: 관리실 정기 | B56: 서정민 | E56: 카드
B60: 소계 | C60: =sum(C56:C59) -> 0
A61: 관리실 일일
B70: 소계 | C70: =SUM(C61:C69) -> 0
A71: 일반 정기 | B71: 성화세계 | E71: 카드
B72: 권혁구 | E72: 카드
B73: 박성준 | E73: 카드
B74: 맘스터치 | E74: 카드 | F74: 60분40매,30분20매
B75: 최성제치과 | E75: 카드 | F75: 60분20매,30분60매,10분100매
B76: 감주영 | E76: 카드
B77: 신형철 | E77: 카드
B78: 이종성 | E78: 카드
B79: 정성우 | E79: 카드
B80: 임성환 | E80: 카드
B81: 이영식 | E81: 카드
B82: 이상옥 | E82: 카드
B83: 최금강 | E83: 카드
B85: 소계 | C85: =sum(C71:C84) -> 0 | G85: 비 고 | H85: 모두의 주차 매출
...

Sheet 26년 06월
A1: [ 6월 주차 매출 내역 ]
A2: 거래처 구분 | B2: 거래처 | C2: 매출액(VAT포함) | D2: 매출(입금)일 | E2: 결재형태 | F2: 비고
A3: 입주사
B15: 소계 | C15: =sum(C3:C14) -> 0
A16: 직원정기
B35: 소계 | C35: =sum(C16:C34) -> 0
A36: 직원일일
B55: 소계 | C55: =sum(C36:C54) -> 0
A56: 관리실 정기
B60: 소계 | C60: =sum(C56:C58) -> 0
A61: 관리실 일일
B70: 소계 | C70: =SUM(C61:C69) -> 0
A71: 일반 정기
B85: 소계 | C85: =sum(C71:C84) -> 0 | G85: 비고 | H85: 모두의 주차 매출
A86: 일일매출
B117: 소계 | C117: =sum(C86:C116) -> 0
A118: 합계 | C118: =sumif(B:B, "소계", C:C) -> 0 | H118: =SUM(H86:H117) -> 0
B120: 계산서 | C120: =sumif(E:E, "계산서", C:C) -> 0
B121: 현금
B122: 카드 | C122: =sumif(E:E, "카드", C:C) -> 0
B123: 모주 | C123: =H118 -> 0
B124: 합계 | C124: =sum(C120:C123) -> 0
B126: 카드수수료
B127: 모주수수료 | C127: =H118*0.25 -> 0
B128: 【주차장 영업 방향의 세분화】 1. 장기 및 영업 충성도가 높음이 예상되는 업체 2. 단기 1일 주차_인근 공사 등 ◎ 1일 주차 전일권 50,000원
B129: 일일주차:(8시간30,000원)

Sheet 26년 07월
A1: [ 7월 주차 매출 내역 ]
A2: 거래처 구분 | B2: 거래처 | C2: 매출액(VAT포함) | D2: 매출(입금)일 | E2: 결재형태 | F2: 비고
A3: 입주사
B15: 소계 | C15: =SUM(C3:C14) -> 0
A16: 직원정기
B35: 소계 | C35: =SUM(C16:C34) -> 0
A36: 직원일일
B55: 소계 | C55: =SUM(C36:C54) -> 0
A56: 관리실 정기
B60: 소계 | C60: =SUM(C56:C59) -> 0
A61: 관리실 일일
B70: 소계 | C70: =SUM(C61:C69) -> 0
A71: 일반 정기
B85: 소계 | C85: =SUM(C71:C84) -> 0 | G85: 비고 | H85: 모두의 주차 매출
A86: 일일매출
B117: 소계 | C117: =sum(C86:C116) -> 0
A118: 합계 | C118: =sumif(B:B, "소계", C:C) -> 0 | H118: =SUM(H86:H117) -> 0
B120: 계산서 | C120: =sumif(E:E, "계산서", C:C) -> 0
B121: 현금
B122: 카드 | C122: =sumif(E:E, "카드", C:C) -> 0
B123: 모주 | C123: =H118 -> 0
B124: 합계 | C124: =sum(C120:C123) -> 0
B126: 카드수수료
B127: 모주수수료 | C127: =H118*0.25 -> 0
B128: 【주차장 영업 방향의 세분화】 1. 장기 및 영업 충성도가 높음이 예상되는 업체 2. 단기 1일 주차_인근 공사 등 ◎ 1일 주차 전일권 50,000원
B129: 일일주차:(8시간30,000원)

Sheet 26년 08월
A1: [ 8월 주차 매출 내역 ]
A2: 거래처 구분 | B2: 거래처 | C2: 매출액(VAT포함) | D2: 매출(입금)일 | E2: 결재형태 | F2: 비고
A3: 입주사
B15: 소계 | C15: =SUM(C3:C14) -> 0
A16: 직원정기
B35: 소계 | C35: =SUM(C16:C34) -> 0
A36: 직원일일
B55: 소계 | C55: =SUM(C36:C54) -> 0
A56: 관리실 정기
B60: 소계 | C60: =SUM(C56:C59) -> 0
A61: 관리실 일일
B70: 소계 | C70: =SUM(C61:C69) -> 0
A71: 일반 정기
B85: 소계 | C85: =SUM(C71:C84) -> 0 | G85: 비고 | H85: 모두의 주차 매출
A86: 일일매출
A118: 합계 | C118: =sumif(B:B, "소계", C:C) -> 0 | H118: =SUM(H86:H117) -> 0
B120: 계산서 | C120: =sumif(E:E, "계산서", C:C) -> 0
B121: 현금
B122: 카드 | C122: =sumif(E:E, "카드", C:C) -> 0
B123: 모주 | C123: =H118 -> 0
B124: 합계 | C124: =sum(C120:C123) -> 0
B126: 카드수수료
B127: 모주수수료 | C127: =H118*0.25 -> 0
B128: 【주차장 영업 방향의 세분화】 1. 장기 및 영업 충성도가 높음이 예상되는 업체 2. 단기 1일 주차_인근 공사 등 ◎ 1일 주차 전일권 50,000원
B129: 일일주차:(8시간30,000원)

Sheet 26년 09월
A1: [ 9월 주차 매출 내역 ]
A2: 거래처 구분 | B2: 거래처 | C2: 매출액(VAT포함) | D2: 매출(입금)일 | E2: 결재형태 | F2: 비고
A3: 입주사
B15: 소계 | C15: =SUM(C3:C14) -> 0
A16: 직원정기
B35: 소계 | C35: =SUM(C16:C34) -> 0
A36: 직원일일
B55: 소계 | C55: =SUM(C36:C54) -> 0
A56: 관리실 정기
B60: 소계 | C60: =SUM(C56:C59) -> 0
A61: 관리실 일일
B70: 소계 | C70: =SUM(C61:C69) -> 0
A71: 일반 정기
B85: 소계 | C85: =SUM(C71:C84) -> 0 | G85: 비고 | H85: 모두의 주차 매출 | J85: 일일주차 취소내역
A86: 일일매출 | B86: 월
B87: 화
B88: 수
B89: 목
B90: 금
B91: 토
B92: 일
B93: 월
B94: 화
B95: 수
B96: 목
B97: 금
B98: 토
... B115: 화
B118: 소계 | H118: =SUM(H86:H117) -> 0
A119: 합계 | C119: =sumif(B:B, "소계", C:C) -> 0
B121: 계산서 | C121: =sumif(E:E, "계산서", C:C) -> 0
B122: 현금
B123: 카드 | C123: =sumif(E:E, "카드", C:C) -> 0
B124: 모주 | C124: =H119
B125: 합계 | C125: =sum(C121:C124) -> 0
B127: 카드수수료
B128: 모주수수료 | C128: =H118*0.25 -> 0
B129: 【주차장 영업 방향의 세분화】 1. 장기 및 영업 충성도가 높음이 예상되는 업체 2. 단기 1일 주차_인근 공사 등 ◎ 1일 주차 전일권 50,000원
B130: 일일주차:(8시간30,000원)

Sheet 26년 10월
A1: [ 10월 주차 매출 내역 ]
A2: 거래처 구분 | B2: 거래처 | C2: 매출액(VAT포함) | D2: 매출(입금)일 | E2: 결재형태 | F2: 비고
A3: 입주사
B15: 소계 | C15: =SUM(C3:C14) -> 0
A16: 직원정기
B35: 소계 | C35: =SUM(C16:C34) -> 0
A36: 직원일일
B55: 소계 | C55: =SUM(C36:C54) -> 0
A56: 관리실 정기
B60: 소계 | C60: =SUM(C56:C59) -> 0
A61: 관리실 일일
B70: 소계 | C70: =SUM(C61:C69) -> 0
A71: 일반 정기
B85: 소계 | C85: =SUM(C71:C84) -> 0 | G85: 비고 | H85: 모두의 주차 매출
A86: 일일매출
B117: 소계 | C117: =sum(C86:C116) -> 0
A118: 합계 | C118: =sumif(B:B, "소계", C:C) -> 0 | H118: =sum(H86:H117) -> 0
B120: 계산서 | C120: =sumif(E:E, "계산서", C:C) -> 0
B121: 현금
B122: 카드 | C122: =sumif(E:E, "카드", C:C) -> 0
B123: 모주 | C123: =H118 -> 0
B124: 합계 | C124: =sum(C120:C123) -> 0
B126: 카드수수료
B127: 모주수수료 | C127: =H118*0.25 -> 0
B128: 【주차장 영업 방향의 세분화】 1. 장기 및 영업 충성도가 높음이 예상되는 업체 2. 단기 1일 주차_인근 공사 등 ◎ 1일 주차 전일권 50,000원
B129: 일일주차:(8시간30,000원)

Sheet 26년 11월
A1: [ 11월 주차 매출 내역 ]
A2: 거래처 구분 | B2: 거래처 | C2: 매출액(VAT포함) | D2: 매출(입금)일 | E2: 결재형태 | F2: 비고
A3: 입주사
B15: 소계 | C15: =SUM(C3:C14) -> 0
A16: 직원정기
B34: 소계 | C34: =SUM(C16:C33) -> 0
A35: 직원일일
B54: 소계 | C54: =SUM(C35:C53) -> 0
A55: 관리실 정기
B59: 소계 | C59: =SUM(C55:C58) -> 0
A60: 관리실 일일
B69: 소계 | C69: =SUM(C60:C68) -> 0
A70: 일반 정기
B84: 소계 | C84: =SUM(C70:C83) -> 0 | G84: 비고 | H84: 모두의 주차 매출
A85: 일일매출
B116: 소계 | C116: =sum(C85:C115) -> 0
A117: 합계 | C117: =sumif(B:B, "소계", C:C) -> 0
H118: =sum(H85:H116) -> 0
B119: 계산서 | C119: =sumif(E:E, "계산서", C:C) -> 0
B120: 현금
B121: 카드 | C121: =sumif(E:E, "카드", C:C) -> 0
B122: 모주 | C122: =H118 -> 0
B123: 합계 | C123: =sum(C119:C122) -> 0
B125: 카드수수료
B126: 모주수수료 | C126: =H118*0.25 -> 0
B127: 【주차장 영업 방향의 세분화】 1. 장기 및 영업 충성도가 높음이 예상되는 업체 2. 단기 1일 주차_인근 공사 등 ◎ 1일 주차 전일권 50,000원
B128: 일일주차:(8시간30,000원)

Sheet 26년 12월
A1: [ 12월 주차 매출 내역 ]
A2: 거래처 구분 | B2: 거래처 | C2: 매출액(VAT포함) | D2: 매출(입금)일 | E2: 결재형태 | F2: 비고
A3: 입주사
B15: 소계 | C15: =SUM(C3:C14) -> 0
A16: 직원정기
B35: 소계 | C35: =SUM(C16:C34) -> 0
A36: 직원일일
B55: 소계 | C55: =SUM(C36:C54) -> 0
A56: 관리실 정기
B60: 소계 | C60: =SUM(C56:C59) -> 0
A61: 관리실 일일 | E61: 카드
E62: 카드
E63: 카드
E64: 카드
E65: 카드
B70: 소계 | C70: =SUM(C61:C69) -> 0
A71: 일반 정기
B85: 소계 | C85: =SUM(C71:C84) -> 0 | G85: 비고 | H85: 모두의 주차 매출
A86: 일일매출
B117: 소계 | C117: =sum(C86:C116) -> 0
A118: 합계 | C118: =sumif(B:B, "소계", C:C) -> 0 | H118: =sum(H86:H117) -> 0
B120: 계산서 | C120: =sumif(E:E, "계산서", C:C) -> 0
B121: 현금
B122: 카드 | C122: =sumif(E:E, "카드", C:C) -> 0
B123: 모주 | C123: =H118 -> 0
B124: 합계 | C124: =sum(C120:C123) -> 0
B126: 카드수수료
B127: 모주수수료 | C127: =H118*0.25 -> 0
B128: 【주차장 영업 방향의 세분화】 1. 장기 및 영업 충성도가 높음이 예상되는 업체 2. 단기 1일 주차_인근 공사 등 ◎ 1일 주차 전일권 50,000원
B129: 일일주차:(8시간30,000원)

Sheet Total
A1: [ 2026년 월별 주차장 매출 내역서 ]
N2: [VAT포함]
A3: 구 분 | B3: 1월 | C3: 2월 | D3: 3월 | E3: 4월 | F3: 5월 | G3: 6월 | H3: 7월 | I3: 8월 | J3: 9월 | K3: 10월 | L3: 11월 | M3: 12월 | N3: 합계 | O3: 비중
A4: 입주사 | B4: ='26년 01월'!$C$15 -> 860000 | C4: ='26년 02월'!C15 -> 992000 | D4: ='26년 03월'!C15 -> 660000 | E4: ='26년 04월'!C15 -> 728000 | F4: ='26년 05월'!C15 -> 0 | G4: ='26년 06월'!C15 -> 0 | H4: ='26년 07월'!C15 -> 0 | I4: ='26년 08월'!C15 -> 0 | J4: ='26년 09월'!C15 -> 0 | K4: ='26년 10월'!C15 -> 0 | L4: ='26년 11월'!C15 -> 0 | M4: ='26년 12월'!C15 -> 0 | N4: =sum(B4:M4) -> 3240000 | O4: =N4/N12 -> 0.059917525
A5: 직원정기 | B5: ='26년 01월'!$C$35 -> 720000 | C5: ='26년 02월'!C35 -> 560000 | D5: ='26년 03월'!C35 -> 640000 | E5: ='26년 04월'!C35 -> 640000 | F5: ='26년 05월'!C35 -> 0 | G5: ='26년 06월'!C35 -> 0 | H5: ='26년 07월'!C35 -> 0 | I5: ='26년 08월'!C35 -> 0 | J5: ='26년 09월'!C35 -> 0 | K5: ='26년 10월'!C35 -> 0 | L5: ='26년 11월'!C34 -> 0 | M5: ='26년 12월'!C35 -> 0 | N5: =sum(B5:M5) -> 2560000 | O5: =N5/N12 -> 0.047342242
A6: 직원일일 | B6: ='26년 01월'!$C$55 -> 160000 | C6: ='26년 02월'!C55 -> 150000 | D6: ='26년 03월'!C55 -> 80000 | E6: ='26년 04월'!C55 -> 70000 | F6: ='26년 05월'!C55 -> 0 | G6: ='26년 06월'!C55 -> 0 | H6: ='26년 07월'!C55 -> 0 | I6: ='26년 08월'!C55 -> 0 | J6: ='26년 09월'!C55 -> 0 | K6: ='26년 10월'!C55 -> 0 | L6: ='26년 11월'!C54 -> 0 | M6: ='26년 12월'!C55 -> 0 | N6: =sum(B6:M6) -> 460000 | O6: =N6/N12 -> 0.0085068091
A7: 관리실정기 | B7: ='26년 01월'!$C$60 -> 80000 | C7: ='26년 02월'!C60 -> 80000 | D7: ='26년 03월'!C60 -> 80000 | E7: ='26년 04월'!C60 -> 80000 | F7: ='26년 05월'!C60 -> 0 | G7: ='26년 06월'!C60 -> 0 | H7: ='26년 07월'!C60 -> 0 | I7: ='26년 08월'!C60 -> 0 | J7: ='26년 09월'!C60 -> 0 | K7: ='26년 10월'!C60 -> 0 | L7: ='26년 11월'!C59 -> 0 | M7: ='26년 12월'!C60 -> 0 | N7: =sum(B7:M7) -> 320000 | O7: =N7/N12 -> 0.0059177802
A8: 관리실일일 | B8: ='26년 01월'!$C$70 -> 0 | C8: ='26년 02월'!C70 -> 0 | D8: ='26년 03월'!C70 -> 0 | E8: ='26년 04월'!C70 -> 0 | F8: ='26년 05월'!C70 -> 0 | G8: ='26년 06월'!C70 -> 0 | H8: ='26년 07월'!C70 -> 0 | I8: ='26년 08월'!C70 -> 0 | J8: ='26년 09월'!C70 -> 0 | K8: ='26년 10월'!C70 -> 0 | L8: ='26년 11월'!C69 -> 0 | M8: ='26년 12월'!C70 -> 0 | N8: =sum(B8:M8) -> 0 | O8: =N8/N12 -> 0
A9: 일반정기 | B9: ='26년 01월'!$C$85 -> 1700000 | C9: ='26년 02월'!C85 -> 1750000 | D9: ='26년 03월'!C85 -> 2283000 | E9: ='26년 04월'!C86 -> 2833330 | F9: ='26년 05월'!C85 -> 0 | G9: ='26년 06월'!C85 -> 0 | H9: ='26년 07월'!C85 -> 0 | I9: ='26년 08월'!C85 -> 0 | J9: ='26년 09월'!C85 -> 0 | K9: ='26년 10월'!C85 -> 0 | L9: ='26년 11월'!C84 -> 0 | M9: ='26년 12월'!C85 -> 0 | N9: =sum(B9:M9) -> 8566330 | O9: =N9/N12 -> 0.15841768
A10: 일반일일 | B10: ='26년 01월'!$C$117 -> 5846000 | C10: ='26년 02월'!C117 -> 4198000 | D10: ='26년 03월'!C117 -> 4834000 | E10: ='26년 04월'!C118 -> 4387000 | F10: ='26년 05월'!C117 -> 0 | G10: ='26년 06월'!C117 -> 0 | H10: ='26년 07월'!C117 -> 0 | I10: ='26년 08월'!C117 | J10: ='26년 09월'!C118 | K10: ='26년 10월'!C117 -> 0 | L10: ='26년 11월'!C116 -> 0 | M10: ='26년 12월'!C117 -> 0 | N10: =sum(B10:M10) -> 19265000 | O10: =N10/N12 -> 0.35626886
A11: 모두의주차 | B11: ='26년 01월'!$H$118 -> 4994000 | C11: ='26년 02월'!$H$118 -> 4861000 | D11: ='26년 03월'!$H$118 -> 5577000 | E11: ='26년 04월'!$H$119 -> 4231000 | F11: ='26년 05월'!$H$118 -> 0 | G11: ='26년 06월'!$H$118 -> 0 | H11: ='26년 07월'!$H$118 -> 0 | I11: ='26년 08월'!$H$118 -> 0 | J11: ='26년 09월'!$H$118 -> 0 | K11: ='26년 10월'!$H$118 -> 0 | L11: ='26년 11월'!$H$118 -> 0 | M11: ='26년 12월'!$H$118 -> 0 | N11: =sum(B11:M11) -> 19663000 | O11: =N11/N12 -> 0.3636291
A12: 합계 | B12: =sum(B4:B11) -> 14360000 | C12: =sum(C4:C11) -> 12591000 | D12: =sum(D4:D11) -> 14154000 | E12: =sum(E4:E11) -> 12969330 | F12: =sum(F4:F11) -> 0 | G12: =sum(G4:G11) -> 0 | H12: =sum(H4:H11) -> 0 | I12: =sum(I4:I11) -> 0 | ... M12: =sum(M4:M11) -> 0 | N12: =sum(B12:M12) -> 54074330 | O12: =SUM(O4:O11) -> 1
A13: 25년매출 | B13: 10689000 | C13: 11401000 | D13: 11690000 | E13: 11929000 | F13: 11691000 | G13: 11310000 | H13: 8536000 | I13: 10903000 | J13: 14145000 | K13: 10309000 | L13: 11957000 | M13: 14159000 | N13: 138719000
A14: 24년매출 | B14: 11717000 | C14: 11111000 | D14: 10069010 | E14: 11494000 | F14: 10482000 | G14: 10781000 | H14: 11611000 | I14: 12000000 | J14: 12568000 | K14: 13608000 | L14: 11853000 | M14: 14387000 | N14: =sum(B14:M14) -> 141681010
A15: 23년매출 | B15: 10371000 | C15: 10190000 | D15: 10912000 | E15: 10491000 | F15: 9625000 | G15: 9367000 | H15: 10459000 | I15: 9650000 | J15: 8945000 | K15: 8803000 | L15: 8347000 | M15: 10465000 | N15: 117625000
A16: 25년 매출대비 | B16: =B12-B13 -> 3671000 | C16: =C12-C13 -> 1190000 | D16: =D12-D13 -> 2464000 | E16: =E12-E13 -> 1040330 | F16: =F12-F13 -> -11691000 | G16: =G12-G13 -> -11310000 | H16: =H12-H13 -> -8536000 | I16: =I12-I13 -> -10903000 | ... N16: =N12-N13 -> -84644670
A17: 24년 매출대비 | B17: =B12-B14 -> 2643000 | C17: =C12-C14 -> 1480000 | D17: =D12-D14 -> 4084990 | E17: =E12-E14 -> 1475330 | F17: =F12-F14 -> -10482000 | G17: =G12-G14 -> -10781000 | H17: =H12-H14 -> -11611000 | I17: =I12-I14 -> -12000000 | ... N17: =N12-N14 -> -87606680
A18: 23년 매출대비 | B18: =B12-B15 -> 3989000 | C18: =C12-C15 -> 2401000 | D18: =D12-D15 -> 3242000 | E18: =E12-E15 -> 2478330 | F18: =F12-F15 -> -9625000 | G18: =G12-G15 -> -9367000 | H18: =H12-H15 -> -10459000 | I18: =I12-I15 -> -9650000 | ... N18: =N12-N15 -> -63550670
C20: 구분 | D20: 1Q | E20: 2Q | F20: 3Q | G20: 4Q | H20: 합계
C21: 2026년 | D21: =sum(B12:D12) -> 41105000 | E21: =sum(E12:G12) -> 12969330 | F21: =sum(H12:J12) -> 0 | G21: =sum(K12:M12) -> 0 | H21: =SUM(D21:G21) -> 54074330
C22: 2025년 | D22: 33780000 | E22: 34930000 | F22: 33584000 | G22: 36425000 | H22: 138719000
C23: 2024년 | D23: 32897010 | E23: 32757000 | F23: 36179000 | G23: 39848000 | H23: 141681010
